Exception on /telegram_web_geo/1141685563 [POST]
Traceback (most recent call last):
  File "C:\Users\111\PycharmProjects\bot_MIIT_project_1\venv\lib\site-packages\flask\app.py", line 2525, in wsgi_app
    response = self.full_dispatch_request()
  File "C:\Users\111\PycharmProjects\bot_MIIT_project_1\venv\lib\site-packages\flask\app.py", line 1822, in full_dispatch_request
    rv = self.handle_user_exception(e)
  File "C:\Users\111\PycharmProjects\bot_MIIT_project_1\venv\lib\site-packages\flask\app.py", line 1820, in full_dispatch_request
    rv = self.dispatch_request()
  File "C:\Users\111\PycharmProjects\bot_MIIT_project_1\venv\lib\site-packages\flask\app.py", line 1796, in dispatch_request
    return self.ensure_sync(self.view_functions[rule.endpoint])(**view_args)
  File "C:\Users\111\PycharmProjects\bot_MIIT_project_1\main.py", line 42, in index
    if data_[1] == 3:
TypeError: 'NoneType' object is not subscriptable
500 Internal Server Error: The server encountered an internal error and was unable to complete your request. Either the server is overloaded or there is an error in the application.
